<?xml version="1.0" encoding="utf-8"?>
<!-- This URDF was automatically created by SolidWorks to URDF Exporter! Originally created by Stephen Brawner (brawner@gmail.com) 
     Commit Version: 1.6.0-4-g7f85cfe  Build Version: 1.6.7995.38578
     For more information, please see http://wiki.ros.org/sw_urdf_exporter -->
<robot
  name="Q20B">
  <link
    name="base_link">
    <inertial>
      <origin
        xyz="0.00056518 0.0086878 -0.015825"
        rpy="0 0 0" />
      <mass
        value="32.139" />
      <inertia
        ixx="0.31344"
        ixy="0.013454"
        ixz="0.0043206"
        iyy="1.4922"
        iyz="0.006401"
        izz="1.6535" />
    </inertial>
    <visual>
      <origin
        xyz="0 0 0"
        rpy="0 0 0" />
      <geometry>
        <mesh
          filename="../meshes/base_link.STL" />
      </geometry>
      <material
        name="">
        <color
          rgba="0.79608 0.82353 0.93725 1" />
      </material>
    </visual>
    <collision>
      <origin xyz="0 0 0" rpy="0 0 0" />
      <geometry>
        <box size="0.44 0.26 0.15"/>
      </geometry>
    </collision>
  </link>
  <link
    name="FL_hip">
    <inertial>
      <origin
        xyz="-0.0042186 -0.017206 0.0015354"
        rpy="0 0 0" />
      <mass
        value="1.5669" />
      <inertia
        ixx="0.0021297"
        ixy="0.00022543"
        ixz="1.057E-05"
        iyy="0.0030626"
        iyz="2.385E-05"
        izz="0.0027139" />
    </inertial>
    <visual>
      <origin
        xyz="0 0 0"
        rpy="0 0 0" />
      <geometry>
        <mesh
          filename="../meshes/FL_hip.STL" />
      </geometry>
      <material
        name="">
        <color
          rgba="0.79608 0.82353 0.93725 1" />
      </material>
    </visual>
  </link>
  <joint
    name="FL_hip_joint"
    type="revolute">
    <origin
      xyz="0.291 0.08 -0.0094"
      rpy="0 0 0" />
    <parent
      link="base_link" />
    <child
      link="FL_hip" />
    <axis xyz="-1 0 0" />
    <dynamics damping="0.01" friction="0.03"/>
    <limit lower="-0.4" upper="0.7" effort="84" velocity="20" />
  </joint>
  <link
    name="FL_thigh">
    <inertial>
      <origin
        xyz="-0.0058481 -0.033986 -0.048708"
        rpy="0 0 0" />
      <mass
        value="4.4613" />
      <inertia
        ixx="0.047153"
        ixy="0.00084876"
        ixz="-0.0037846"
        iyy="0.047563"
        iyz="0.0072907"
        izz="0.011121" />
    </inertial>
    <visual>
      <origin
        xyz="0 0 0"
        rpy="0 0 0" />
      <geometry>
        <mesh
          filename="../meshes/FL_thigh.STL" />
      </geometry>
      <material
        name="">
        <color
          rgba="0.79608 0.82353 0.93725 1" />
      </material>
    </visual>
    <collision>
      <origin xyz="-0.02 0 -0.13" />
      <geometry>
        <cylinder length="0.25" radius="0.04"/>
      </geometry>
    </collision>
  </link>
  <joint
    name="FL_thigh_joint"
    type="revolute">
    <origin
      xyz="0 0.12275 0"
      rpy="0 0 0" />
    <parent
      link="FL_hip" />
    <child
      link="FL_thigh" />
    <axis xyz="0 -1 0" />
    <dynamics damping="0.01" friction="0.03"/>
    <limit lower="-2.9" upper="0.75" effort="84" velocity="20" />
  </joint>
  <link
    name="FL_calf">
    <inertial>
      <origin
        xyz="0.010057 0.0012185 -0.18232"
        rpy="0 0 0" />
      <mass
        value="0.7289" />
      <inertia
        ixx="0.012017"
        ixy="-1.251E-05"
        ixz="0.00024388"
        iyy="0.012339"
        iyz="5.128E-05"
        izz="0.00049297" />
    </inertial>
    <visual>
      <origin
        xyz="0 0 0"
        rpy="0 0 0" />
      <geometry>
        <mesh
          filename="../meshes/FL_calf.STL" />
      </geometry>
      <material
        name="">
        <color
          rgba="0.79608 0.82353 0.93725 1" />
      </material>
    </visual>
    <collision>
      <origin xyz="0.00 0 -0.155" />
      <geometry>
        <cylinder length="0.22" radius="0.025"/>
      </geometry>
    </collision>
  </link>
  <joint
    name="FL_calf_joint"
    type="revolute">
    <origin
      xyz="-0.010846 -0.001 -0.2998"
      rpy="0 0 0" />
    <parent
      link="FL_thigh" />
    <child
      link="FL_calf" />
    <axis xyz="0 -1 0" />
    <dynamics damping="0.01" friction="0.03"/>
    <limit lower="0.593" upper="2.686" effort="160" velocity="20" /> 
  </joint>
  <link name="FL_foot">
    <inertial>
      <mass value="0.06" />
      <inertia ixx="1e-12" ixy="0" ixz="0" iyy="1e-12" iyz="0" izz="1e-12" />
    </inertial>
    <collision>
      <geometry>
        <sphere radius="0.03"/>
      </geometry>
    </collision>
  </link>
  <joint name="FL_foot_joint" type="fixed" dont_collapse="true">
    <origin xyz="0 0 -0.31"/>
    <parent link="FL_calf" />
    <child link="FL_foot" />
  </joint>
  <link
    name="FR_hip">
    <inertial>
      <origin
        xyz="-0.0042188 0.017206 0.0013274"
        rpy="0 0 0" />
      <mass
        value="1.5669" />
      <inertia
        ixx="0.0021305"
        ixy="-0.00022543"
        ixz="1.218E-05"
        iyy="0.0030636"
        iyz="-3.513E-05"
        izz="0.002714" />
    </inertial>
    <visual>
      <origin
        xyz="0 0 0"
        rpy="0 0 0" />
      <geometry>
        <mesh
          filename="../meshes/FR_hip.STL" />
      </geometry>
      <material
        name="">
        <color
          rgba="0.79608 0.82353 0.93725 1" />
      </material>
    </visual>
  </link>
  <joint
    name="FR_hip_joint"
    type="revolute">
    <origin
      xyz="0.291 -0.08 -0.0094"
      rpy="0 0 0" />
    <parent
      link="base_link" />
    <child
      link="FR_hip" />
    <axis xyz="-1 0 0" />
    <dynamics damping="0.01" friction="0.03"/>
    <limit lower="-0.7" upper="0.4" effort="84" velocity="20" />
  </joint>
  <link
    name="FR_thigh">
    <inertial>
      <origin
        xyz="-0.0081687 0.032954 -0.047777"
        rpy="0 0 0" />
      <mass
        value="4.4487" />
      <inertia
        ixx="0.04644"
        ixy="-0.0011634"
        ixz="-0.0039558"
        iyy="0.046896"
        iyz="-0.0069519"
        izz="0.010808" />
    </inertial>
    <visual>
      <origin
        xyz="0 0 0"
        rpy="0 0 0" />
      <geometry>
        <mesh
          filename="../meshes/FR_thigh.STL" />
      </geometry>
      <material
        name="">
        <color
          rgba="0.79608 0.82353 0.93725 1" />
      </material>
    </visual>
    <collision>
      <origin xyz="-0.02 0 -0.13" />
      <geometry>
        <cylinder length="0.25" radius="0.04"/>
      </geometry>
    </collision>
  </link>
  <joint
    name="FR_thigh_joint"
    type="revolute">
    <origin
      xyz="0 -0.12275 0"
      rpy="0 0 0" />
    <parent
      link="FR_hip" />
    <child
      link="FR_thigh" />
    <axis xyz="0 -1 0" />
    <dynamics damping="0.01" friction="0.03"/>
    <limit lower="-2.9" upper="0.75" effort="84" velocity="20" />
  </joint>
  <link
    name="FR_calf">
    <inertial>
      <origin
        xyz="0.010056 -0.0012 -0.18227"
        rpy="0 0 0" />
      <mass
        value="0.72911" />
      <inertia
        ixx="0.012023"
        ixy="1.266E-05"
        ixz="0.00024397"
        iyy="0.012345"
        iyz="-4.96E-05"
        izz="0.00049301" />
    </inertial>
    <visual>
      <origin
        xyz="0 0 0"
        rpy="0 0 0" />
      <geometry>
        <mesh
          filename="../meshes/FR_calf.STL" />
      </geometry>
      <material
        name="">
        <color
          rgba="0.79608 0.82353 0.93725 1" />
      </material>
    </visual>
    <collision>
      <origin xyz="0.00 0 -0.155" />
      <geometry>
        <cylinder length="0.22" radius="0.025"/>
      </geometry>
    </collision>
  </link>
  <joint
    name="FR_calf_joint"
    type="revolute">
    <origin
      xyz="-0.010846 0.001 -0.2998"
      rpy="0 0 0" />
    <parent
      link="FR_thigh" />
    <child
      link="FR_calf" />
    <axis xyz="0 -1 0" />
    <dynamics damping="0.01" friction="0.03"/>
    <limit lower="0.593" upper="2.686" effort="160" velocity="20" /> 
  </joint>
  <link name="FR_foot">
    <inertial>
      <mass value="0.06" />
      <inertia ixx="1e-12" ixy="0" ixz="0" iyy="1e-12" iyz="0" izz="1e-12" />
    </inertial>
    <collision>
      <geometry>
        <sphere radius="0.03"/>
      </geometry>
    </collision>
  </link>
  <joint name="FR_foot_joint" type="fixed" dont_collapse="true">
    <origin xyz="0 0 -0.31"/>
    <parent link="FR_calf" />
    <child link="FR_foot" />
  </joint>
  <link
    name="RL_hip">
    <inertial>
      <origin
        xyz="0.0042188 -0.017206 0.0013274"
        rpy="0 0 0" />
      <mass
        value="1.5669" />
      <inertia
        ixx="0.0021305"
        ixy="-0.00022543"
        ixz="-1.218E-05"
        iyy="0.0030636"
        iyz="3.513E-05"
        izz="0.002714" />
    </inertial>
    <visual>
      <origin
        xyz="0 0 0"
        rpy="0 0 0" />
      <geometry>
        <mesh
          filename="../meshes/RL_hip.STL" />
      </geometry>
      <material
        name="">
        <color
          rgba="0.79608 0.82353 0.93725 1" />
      </material>
    </visual>
  </link>
  <joint
    name="RL_hip_joint"
    type="revolute">
    <origin
      xyz="-0.291 0.08 -0.0094"
      rpy="0 0 0" />
    <parent
      link="base_link" />
    <child
      link="RL_hip" />
    <axis xyz="-1 0 0" />
    <dynamics damping="0.01" friction="0.03"/>
    <limit lower="-0.4" upper="0.7" effort="84" velocity="20" />
  </joint>
  <link
    name="RL_thigh">
    <inertial>
      <origin
        xyz="-0.0082841 -0.034031 -0.048895"
        rpy="0 0 0" />
      <mass
        value="4.451" />
      <inertia
        ixx="0.047108"
        ixy="0.001139"
        ixz="-0.0039817"
        iyy="0.047583"
        iyz="0.0071818"
        izz="0.01116" />
    </inertial>
    <visual>
      <origin
        xyz="0 0 0"
        rpy="0 0 0" />
      <geometry>
        <mesh
          filename="../meshes/RL_thigh.STL" />
      </geometry>
      <material
        name="">
        <color
          rgba="0.79608 0.82353 0.93725 1" />
      </material>
    </visual>
    <collision>
      <origin xyz="-0.02 0 -0.13" />
      <geometry>
        <cylinder length="0.25" radius="0.04"/>
      </geometry>
    </collision>
  </link>
  <joint
    name="RL_thigh_joint"
    type="revolute">
    <origin
      xyz="0 0.12275 0"
      rpy="0 0 0" />
    <parent
      link="RL_hip" />
    <child
      link="RL_thigh" />
    <axis xyz="0 -1 0" />
    <dynamics damping="0.01" friction="0.03"/>
    <limit lower="-2.9" upper="0.75" effort="84" velocity="20" />
  </joint>
  <link
    name="RL_calf">
    <inertial>
      <origin
        xyz="0.010057 0.0012185 -0.18232"
        rpy="0 0 0" />
      <mass
        value="0.7289" />
      <inertia
        ixx="0.012017"
        ixy="-1.251E-05"
        ixz="0.00024388"
        iyy="0.012339"
        iyz="5.128E-05"
        izz="0.00049297" />
    </inertial>
    <visual>
      <origin
        xyz="0 0 0"
        rpy="0 0 0" />
      <geometry>
        <mesh
          filename="../meshes/RL_calf.STL" />
      </geometry>
      <material
        name="">
        <color
          rgba="0.79608 0.82353 0.93725 1" />
      </material>
    </visual>
    <collision>
      <origin xyz="0.00 0 -0.155" />
      <geometry>
        <cylinder length="0.22" radius="0.025"/>
      </geometry>
    </collision>
  </link>
  <joint
    name="RL_calf_joint"
    type="revolute">
    <origin
      xyz="-0.010846 -0.001 -0.2998"
      rpy="0 0 0" />
    <parent
      link="RL_thigh" />
    <child
      link="RL_calf" />
    <axis xyz="0 -1 0" />
    <dynamics damping="0.01" friction="0.03"/>
    <limit lower="0.593" upper="2.686" effort="160" velocity="20" /> 
  </joint>
  <link name="RL_foot">
    <inertial>
      <mass value="0.06" />
      <inertia ixx="1e-12" ixy="0" ixz="0" iyy="1e-12" iyz="0" izz="1e-12" />
    </inertial>
    <collision>
      <geometry>
        <sphere radius="0.03"/>
      </geometry>
    </collision>
  </link>
  <joint name="RL_foot_fixed" type="fixed" dont_collapse="true">
    <origin xyz="0 0 -0.31"/>
    <parent link="RL_calf" />
    <child link="RL_foot" />
  </joint>
  <link
    name="RR_hip">
    <inertial>
      <origin
        xyz="0.0042186 0.017206 0.0015354"
        rpy="0 0 0" />
      <mass
        value="1.5669" />
      <inertia
        ixx="0.0021297"
        ixy="0.00022543"
        ixz="-1.057E-05"
        iyy="0.0030626"
        iyz="-2.385E-05"
        izz="0.0027139" />
    </inertial>
    <visual>
      <origin
        xyz="0 0 0"
        rpy="0 0 0" />
      <geometry>
        <mesh
          filename="../meshes/RR_hip.STL" />
      </geometry>
      <material
        name="">
        <color
          rgba="0.79608 0.82353 0.93725 1" />
      </material>
    </visual>
  </link>
  <joint
    name="RR_hip_joint"
    type="revolute">
    <origin
      xyz="-0.291 -0.08 -0.0094"
      rpy="0 0 0" />
    <parent
      link="base_link" />
    <child
      link="RR_hip" />
    <axis xyz="-1 0 0" />
    <dynamics damping="0.01" friction="0.03"/>
    <limit lower="-0.7" upper="0.4" effort="84" velocity="20" />
  </joint>
  <link
    name="RR_thigh">
    <inertial>
      <origin
        xyz="-0.0083932 0.034958 -0.047771"
        rpy="0 0 0" />
      <mass
        value="4.4154" />
      <inertia
        ixx="0.046096"
        ixy="-0.0011638"
        ixz="-0.0037727"
        iyy="0.046363"
        iyz="-0.0071725"
        izz="0.011181" />
    </inertial>
    <visual>
      <origin
        xyz="0 0 0"
        rpy="0 0 0" />
      <geometry>
        <mesh
          filename="../meshes/RR_thigh.STL" />
      </geometry>
      <material
        name="">
        <color
          rgba="0.79608 0.82353 0.93725 1" />
      </material>
    </visual>
    <collision>
      <origin xyz="-0.02 0 -0.13" />
      <geometry>
        <cylinder length="0.25" radius="0.04"/>
      </geometry>
    </collision>
  </link>
  <joint
    name="RR_thigh_joint"
    type="revolute">
    <origin
      xyz="0 -0.12275 0"
      rpy="0 0 0" />
    <parent
      link="RR_hip" />
    <child
      link="RR_thigh" />
    <axis xyz="0 -1 0" />
    <dynamics damping="0.01" friction="0.03"/>
    <limit lower="-2.9" upper="0.75" effort="84" velocity="20" />
  </joint>
  <link
    name="RR_calf">
    <inertial>
      <origin
        xyz="0.010056 -0.0012 -0.18227"
        rpy="0 0 0" />
      <mass
        value="0.72911" />
      <inertia
        ixx="0.012023"
        ixy="1.266E-05"
        ixz="0.00024397"
        iyy="0.012345"
        iyz="-4.96E-05"
        izz="0.00049301" />
    </inertial>
    <visual>
      <origin
        xyz="0 0 0"
        rpy="0 0 0" />
      <geometry>
        <mesh
          filename="../meshes/RR_calf.STL" />
      </geometry>
      <material
        name="">
        <color
          rgba="0.79608 0.82353 0.93725 1" />
      </material>
    </visual>
    <collision>
      <origin xyz="0.00 0 -0.155" />
      <geometry>
        <cylinder length="0.22" radius="0.025"/>
      </geometry>
    </collision>
  </link>
  <joint
    name="RR_calf_joint"
    type="revolute">
    <origin
      xyz="-0.010846 0.001 -0.2998"
      rpy="0 0 0" />
    <parent
      link="RR_thigh" />
    <child
      link="RR_calf" />
    <axis xyz="0 -1 0" />
    <dynamics damping="0.01" friction="0.03"/>
    <limit lower="0.593" upper="2.686" effort="160" velocity="20" /> 
  </joint>
  <link name="RR_foot">
    <inertial>
      <mass value="0.06" />
      <inertia ixx="1e-12" ixy="0" ixz="0" iyy="1e-12" iyz="0" izz="1e-12" />
    </inertial>
    <collision>
      <geometry>
        <sphere radius="0.03"/>
      </geometry>
    </collision>
  </link>
  <joint name="RR_foot_fixed" type="fixed" dont_collapse="true">
    <origin xyz="0 0 -0.31"/>
    <parent link="RR_calf" />
    <child link="RR_foot" />
  </joint>
</robot>